Workbook

Sheet CODIGOS
A1: CAJA | B1: ENVIO | C1: MONTO | D1: PESO | E1: ADUANA | F1: IMPUESTO | G1: CODIGO | H1: ESTADO | I1: FECHA ENVIO | J1: FECHA LLEGADA | K1: =TODAY() -> 46203 | L1: FECHA ESTIMADA | M1: IMPUESTO PAGADO
A2: 1 | B2: =LOOKUP(A2,ADQUISICIONES!O:O,ADQUISICIONES!P:P) -> 1 | C2: =LOOKUP(A2,ADQUISICIONES!$R$17:$R$63,ADQUISICIONES!$Y$17:$Y$63) -> 1437.8557 | D2: =LOOKUP(A2,ADQUISICIONES!$R$17:$R$63,ADQUISICIONES!$T$17:$T$63) -> 20148 | E2: TRUE | F2: =(C2*18%) -> 258.81402 | G2: CN110167833JP | H2: TRUE | I2: 45894 | J2: 45955 | K2: =J2-I2 -> 61 | L2: =I2+65 -> 45959 | M2: =SUMIF(E:E,TRUE,F:F) -> 2698.5715
A3: 2 | B3: =LOOKUP(A3,ADQUISICIONES!O:O,ADQUISICIONES!P:P) -> 2 | C3: =LOOKUP(A3,ADQUISICIONES!$R$17:$R$63,ADQUISICIONES!$Y$17:$Y$63) -> 1248.3276 | D3: =LOOKUP(A3,ADQUISICIONES!$R$17:$R$63,ADQUISICIONES!$T$17:$T$63) -> 17994 | E3: TRUE | F3: =(C3*18%) -> 224.69896 | G3: CN110110051JP | H3: TRUE | I3: 45894 | J3: 45955 | K3: =J3-I3 -> 61 | L3: =I3+65 -> 45959
A4: 3 | B4: =LOOKUP(A4,ADQUISICIONES!O:O,ADQUISICIONES!P:P) -> 2 | C4: =LOOKUP(A4,ADQUISICIONES!$R$17:$R$63,ADQUISICIONES!$Y$17:$Y$63) -> 1181.4643 | D4: =LOOKUP(A4,ADQUISICIONES!$R$17:$R$63,ADQUISICIONES!$T$17:$T$63) -> 15562 | E4: FALSE | F4: =(C4*18%) -> 212.66358 | G4: CN110593867JP | H4: TRUE | I4: 45899 | J4: 45965 | K4: =J4-I4 -> 66 | L4: =I4+65 -> 45964
A5: 4 | B5: =LOOKUP(A5,ADQUISICIONES!O:O,ADQUISICIONES!P:P) -> 5 | C5: =LOOKUP(A5,ADQUISICIONES!$R$17:$R$63,ADQUISICIONES!$Y$17:$Y$63) -> 1126.6503 | D5: =LOOKUP(A5,ADQUISICIONES!$R$17:$R$63,ADQUISICIONES!$T$17:$T$63) -> 19090 | E5: FALSE | F5: =(C5*18%) -> 202.79706 | G5: CN110868218JP | H5: TRUE | I5: 45899 | J5: 45965 | K5: =J5-I5 -> 66 | L5: =I5+65 -> 45964
A6: 5 | B6: =LOOKUP(A6,ADQUISICIONES!O:O,ADQUISICIONES!P:P) -> 6 | C6: =LOOKUP(A6,ADQUISICIONES!$R$17:$R$63,ADQUISICIONES!$Y$17:$Y$63) -> 1051.0959 | D6: =LOOKUP(A6,ADQUISICIONES!$R$17:$R$63,ADQUISICIONES!$T$17:$T$63) -> 14018 | E6: FALSE | F6: =(C6*18%) -> 189.19726 | G6: CN111297287JP | H6: TRUE | I6: 45915 | J6: 45981 | K6: =J6-I6 -> 66 | L6: =I6+65 -> 45980
A7: 6 | B7: =LOOKUP(A7,ADQUISICIONES!O:O,ADQUISICIONES!P:P) -> 7 | C7: =LOOKUP(A7,ADQUISICIONES!$R$17:$R$63,ADQUISICIONES!$Y$17:$Y$63) -> 1321.6399 | D7: =LOOKUP(A7,ADQUISICIONES!$R$17:$R$63,ADQUISICIONES!$T$17:$T$63) -> 22836 | E7: FALSE | F7: =(C7*18%) -> 237.89519 | G7: CN111293682JP | H7: TRUE | I7: 45915 | J7: 45982 | K7: =J7-I7 -> 67 | L7: =I7+65 -> 45980
A8: 7 | B8: =LOOKUP(A8,ADQUISICIONES!O:O,ADQUISICIONES!P:P) -> 8 | C8: =LOOKUP(A8,ADQUISICIONES!$R$17:$R$63,ADQUISICIONES!$Y$17:$Y$63) -> 348.1431 | D8: =LOOKUP(A8,ADQUISICIONES!$R$17:$R$63,ADQUISICIONES!$T$17:$T$63) -> 1002 | E8: FALSE | F8: =(C8*18%) -> 62.665758 | G8: RN096695531JP | H8: TRUE | I8: 45916 | J8: 45924 | K8: =J8-I8 -> 8 | L8: =I8+65 -> 45981
A9: 8 | B9: =LOOKUP(A9,ADQUISICIONES!O:O,ADQUISICIONES!P:P) -> 10 | C9: =LOOKUP(A9,ADQUISICIONES!$R$17:$R$63,ADQUISICIONES!$Y$17:$Y$63) -> 1438.1026 | D9: =LOOKUP(A9,ADQUISICIONES!$R$17:$R$63,ADQUISICIONES!$T$17:$T$63) -> 25918 | E9: FALSE | F9: =(C9*18%) -> 258.85847 | G9: CN111980519JP | H9: TRUE | I9: 45925 | J9: 45993 | K9: =J9-I9 -> 68 | L9: =I9+65 -> 45990
A10: 9 | B10: 14 | C10: =LOOKUP(A10,ADQUISICIONES!$R$17:$R$63,ADQUISICIONES!$Y$17:$Y$63) -> 1175.02 | D10: =LOOKUP(A10,ADQUISICIONES!$R$17:$R$63,ADQUISICIONES!$T$17:$T$63) -> 16178 | E10: TRUE | F10: =(C10*18%) -> 211.5036 | G10: CN112866696JP | H10: TRUE | I10: 45943 | J10: 46006 | K10: =J10-I10 -> 63 | L10: =I10+65 -> 46008
A11: 10 | B11: 11 | C11: =LOOKUP(A11,ADQUISICIONES!$R$17:$R$63,ADQUISICIONES!$Y$17:$Y$63) -> 1053.3428 | D11: =LOOKUP(A11,ADQUISICIONES!$R$17:$R$63,ADQUISICIONES!$T$17:$T$63) -> 10632 | E11: TRUE | F11: =(C11*18%) -> 189.6017 | G11: CN112692350JP | H11: TRUE | I11: 45941 | J11: 46006 | K11: =J11-I11 -> 65 | L11: =I11+65 -> 46006
A12: 11 | B12: 16 | C12: =LOOKUP(A12,ADQUISICIONES!$R$17:$R$63,ADQUISICIONES!$Y$17:$Y$63) -> 986.52891 | D12: =LOOKUP(A12,ADQUISICIONES!$R$17:$R$63,ADQUISICIONES!$T$17:$T$63) -> 10442 | E12: TRUE | F12: =(C12*18%) -> 177.5752 | G12: CN112966915JP | H12: TRUE | I12: 45941 | J12: 46006 | K12: =J12-I12 -> 65 | L12: =I12+65 -> 46006
A13: 12 | B13: 13 | C13: =LOOKUP(A13,ADQUISICIONES!$R$17:$R$63,ADQUISICIONES!$Y$17:$Y$63) -> 1080.0584 | D13: =LOOKUP(A13,ADQUISICIONES!$R$17:$R$63,ADQUISICIONES!$T$17:$T$63) -> 15170 | E13: TRUE | F13: =(C13*18%) -> 194.41051 | G13: CN113022594JP | H13: TRUE | I13: 45941 | J13: 46006 | K13: =J13-I13 -> 65 | L13: =I13+65 -> 46006
A14: 13 | B14: 17 | C14: =LOOKUP(A14,ADQUISICIONES!$R$17:$R$63,ADQUISICIONES!$Y$17:$Y$63) -> 1063.6142 | D14: =LOOKUP(A14,ADQUISICIONES!$R$17:$R$63,ADQUISICIONES!$T$17:$T$63) -> 14560 | E14: TRUE | F14: =(C14*18%) -> 191.45056 | G14: CN112745313JP | H14: TRUE | I14: 45941 | J14: 46006 | K14: =J14-I14 -> 65 | L14: =I14+65 -> 46006
A15: 14 | B15: 15 | C15: =LOOKUP(A15,ADQUISICIONES!$R$17:$R$63,ADQUISICIONES!$Y$17:$Y$63) -> 1041.9602 | D15: =LOOKUP(A15,ADQUISICIONES!$R$17:$R$63,ADQUISICIONES!$T$17:$T$63) -> 11042 | E15: TRUE | F15: =(C15*18%) -> 187.55284 | G15: CN113018056JP | H15: TRUE | I15: 45941 | J15: 46006 | K15: =J15-I15 -> 65 | L15: =I15+65 -> 46006
A16: 15 | B16: 12 | C16: =LOOKUP(A16,ADQUISICIONES!$R$17:$R$63,ADQUISICIONES!$Y$17:$Y$63) -> 1048.3552 | D16: =LOOKUP(A16,ADQUISICIONES!$R$17:$R$63,ADQUISICIONES!$T$17:$T$63) -> 9450 | E16: TRUE | F16: =(C16*18%) -> 188.70393 | G16: CN113076028JP | H16: TRUE | I16: 45941 | J16: 46006 | K16: =J16-I16 -> 65 | L16: =I16+65 -> 46006 | N16: CN116170521JP
A17: 16 | B17: 18 | C17: =LOOKUP(A17,ADQUISICIONES!$R$17:$R$63,ADQUISICIONES!$Y$17:$Y$63) -> 1225.8094 | D17: =LOOKUP(A17,ADQUISICIONES!$R$17:$R$63,ADQUISICIONES!$T$17:$T$63) -> 16574 | E17: FALSE | F17: =(C17*18%) -> 220.64569 | G17: CN112880698JP | H17: TRUE | I17: 45946 | J17: 46009 | K17: =J17-I17 -> 63 | L17: =I17+65 -> 46011
A18: 17 | B18: =LOOKUP(A18,ADQUISICIONES!O:O,ADQUISICIONES!P:P) -> 19 | C18: =LOOKUP(A18,ADQUISICIONES!$R$17:$R$63,ADQUISICIONES!$Y$17:$Y$63) -> 1294.0306 | D18: =LOOKUP(A18,ADQUISICIONES!$R$17:$R$63,ADQUISICIONES!$T$17:$T$63) -> 15602 | E18: FALSE | F18: =(C18*18%) -> 232.92551 | G18: CN115461531JP | H18: TRUE | I18: 45990 | J18: 46047 | K18: =J18-I18 -> 57 | L18: =I18+65 -> 46055 | M18: FABRIZIO
A19: 18 | B19: 20 | C19: =LOOKUP(A19,ADQUISICIONES!$R$17:$R$63,ADQUISICIONES!$Y$17:$Y$63) -> 1393.0074 | D19: =LOOKUP(A19,ADQUISICIONES!$R$17:$R$63,ADQUISICIONES!$T$17:$T$63) -> 22719 | E19: FALSE | F19: =(C19*18%) -> 250.74133 | G19: CN115298685JP | H19: TRUE | I19: 45990 | J19: 46048 | K19: =J19-I19 -> 58 | L19: =I19+65 -> 46055 | M19: JENNI
A20: 19 | B20: =LOOKUP(A20,ADQUISICIONES!O:O,ADQUISICIONES!P:P) -> 20 | C20: =LOOKUP(A20,ADQUISICIONES!$R$17:$R$63,ADQUISICIONES!$Y$17:$Y$63) -> 1159.2116 | D20: =LOOKUP(A20,ADQUISICIONES!$R$17:$R$63,ADQUISICIONES!$T$17:$T$63) -> 17138 | E20: TRUE | F20: =(C20*18%) -> 208.65808 | G20: CN115427708JP | H20: TRUE | I20: 45993 | J20: 46049 | K20: =J20-I20 -> 56 | L20: =I20+65 -> 46058 | M20: FABRIZIO
A21: 20 | B21: =LOOKUP(A21,ADQUISICIONES!O:O,ADQUISICIONES!P:P) -> 22 | C21: =LOOKUP(A21,ADQUISICIONES!$R$17:$R$63,ADQUISICIONES!$Y$17:$Y$63) -> 1491.8585 | D21: =LOOKUP(A21,ADQUISICIONES!$R$17:$R$63,ADQUISICIONES!$T$17:$T$63) -> 11890 | E21: FALSE | F21: =(C21*18%) -> 268.53453 | G21: CN115756315JP | H21: TRUE | I21: 45993 | J21: 46050 | K21: =J21-I21 -> 57 | L21: =I21+65 -> 46058 | M21: JENNI
A22: 21 | B22: =LOOKUP(A22,ADQUISICIONES!O:O,ADQUISICIONES!P:P) -> 23 | C22: =LOOKUP(A22,ADQUISICIONES!$R$17:$R$63,ADQUISICIONES!$Y$17:$Y$63) -> 1231.864 | D22: =LOOKUP(A22,ADQUISICIONES!$R$17:$R$63,ADQUISICIONES!$T$17:$T$63) -> 17597 | E22: TRUE | F22: =(C22*18%) -> 221.73553 | G22: CN116091585JP | H22: TRUE | I22: 45994 | J22: 46051 | K22: =J22-I22 -> 57 | L22: =I22+65 -> 46059 | M22: FABRIZIO
A23: 22 | B23: =LOOKUP(A23,ADQUISICIONES!O:O,ADQUISICIONES!P:P) -> 24 | C23: =LOOKUP(A23,ADQUISICIONES!$R$17:$R$63,ADQUISICIONES!$Y$17:$Y$63) -> 1146.1044 | D23: =LOOKUP(A23,ADQUISICIONES!$R$17:$R$63,ADQUISICIONES!$T$17:$T$63) -> 14436 | E23: FALSE | F23: =(C23*18%) -> 206.2988 | G23: CN116096826JP | H23: TRUE | I23: 45994 | J23: 46052 | K23: =J23-I23 -> 58 | L23: =I23+65 -> 46059 | M23: JENNI
A24: 23 | B24: 25 | C24: =LOOKUP(A24,ADQUISICIONES!$R$17:$R$63,ADQUISICIONES!$Y$17:$Y$63) -> 2390.4311 | D24: =LOOKUP(A24,ADQUISICIONES!$R$17:$R$63,ADQUISICIONES!$T$17:$T$63) -> 25978 | E24: FALSE | F24: =(C24*18%) -> 430.27761 | G24: CN116147531JP | H24: TRUE | I24: 45994 | J24: 46053 | K24: =J24-I24 -> 59 | L24: =I24+65 -> 46059 | M24: ALEX
B25: 26 | E25: TRUE | G25: CN116170521JP | H25: TRUE | I25: 45996 | J25: 46054 | K25: =J25-I25 -> 58 | L25: =I25+65 -> 46061
A26: 24 | B26: =LOOKUP(A26,ADQUISICIONES!O:O,ADQUISICIONES!P:P) -> 27 | C26: =LOOKUP(A26,ADQUISICIONES!$R$17:$R$63,ADQUISICIONES!$Y$17:$Y$63) -> 1329.8924 | D26: =LOOKUP(A26,ADQUISICIONES!$R$17:$R$63,ADQUISICIONES!$T$17:$T$63) -> 17922 | E26: FALSE | F26: =(C26*18%) -> 239.38062 | G26: CN116172995JP | H26: TRUE | I26: 45996 | J26: 46055 | K26: =J26-I26 -> 59 | L26: =I26+65 -> 46061 | M26: ALEX
A27: 25 | B27: =LOOKUP(A27,ADQUISICIONES!O:O,ADQUISICIONES!P:P) -> 28 | C27: =LOOKUP(A27,ADQUISICIONES!$R$17:$R$63,ADQUISICIONES!$Y$17:$Y$63) -> 1344.3365 | D27: =LOOKUP(A27,ADQUISICIONES!$R$17:$R$63,ADQUISICIONES!$T$17:$T$63) -> 20506 | E27: FALSE | F27: =(C27*18%) -> 241.98057 | G27: CN116006975JP | H27: TRUE | I27: 45996 | J27: 46056 | K27: =J27-I27 -> 60 | L27: =I27+65 -> 46061 | M27: JENNI
A28: 26 | B28: =LOOKUP(A28,ADQUISICIONES!O:O,ADQUISICIONES!P:P) -> 29 | C28: =LOOKUP(A28,ADQUISICIONES!$R$17:$R$63,ADQUISICIONES!$Y$17:$Y$63) -> 1251.126 | D28: =LOOKUP(A28,ADQUISICIONES!$R$17:$R$63,ADQUISICIONES!$T$17:$T$63) -> 17366 | E28: FALSE | F28: =(C28*18%) -> 225.20267 | G28: CN118380783JP | H28: TRUE | I28: 46041 | J28: 46111 | K28: =J28-I28 -> 70 | L28: =I28+65 -> 46106
A29: 27 | B29: 30 | C29: =LOOKUP(A29,ADQUISICIONES!R43:R89,ADQUISICIONES!Y43:Y89) -> 1304.2201 | D29: =LOOKUP(A29,ADQUISICIONES!$R$17:$R$63,ADQUISICIONES!$T$17:$T$63) -> 9802 | E29: FALSE | F29: =(C29*18%) -> 234.75962 | G29: CN118380633JP | H29: TRUE | I29: 46041 | J29: 46111 | K29: =J29-I29 -> 70 | L29: =I29+65 -> 46106
A30: 28 | B30: 31 | C30: =LOOKUP(A30,ADQUISICIONES!R44:R90,ADQUISICIONES!Y44:Y90) -> 1017.0248 | D30: =LOOKUP(A30,ADQUISICIONES!$R$17:$R$63,ADQUISICIONES!$T$17:$T$63) -> 12444 | E30: FALSE | F30: =(C30*18%) -> 183.06446 | G30: CN119371712JP | H30: TRUE | I30: 46055 | J30: 46120 | K30: =J30-I30 -> 65 | L30: =I30+65 -> 46120 | M30: ALEX
A31: 29 | B31: =LOOKUP(A31,ADQUISICIONES!O:O,ADQUISICIONES!P:P) -> 31 | C31: =LOOKUP(A31,ADQUISICIONES!R45:R91,ADQUISICIONES!Y45:Y91) -> 0 | D31: =LOOKUP(A31,ADQUISICIONES!$R$17:$R$63,ADQUISICIONES!$T$17:$T$63) -> 0 | E31: FALSE | F31: =(C31*18%) -> 0 | G31: CN120084696JP | H31: TRUE | I31: 46059 | J31: 46123 | K31: =J31-I31 -> 64 | L31: =I31+65 -> 46124
A32: 30 | B32: =LOOKUP(A32,ADQUISICIONES!O:O,ADQUISICIONES!P:P) -> 31 | C32: =LOOKUP(A32,ADQUISICIONES!R46:R92,ADQUISICIONES!Y46:Y92) -> 0 | D32: =LOOKUP(A32,ADQUISICIONES!$R$17:$R$63,ADQUISICIONES!$T$17:$T$63) -> 0 | E32: FALSE | F32: =(C32*18%) -> 0 | G32: CN119974797JP | H32: TRUE | I32: 46059 | J32: 46123 | K32: =J32-I32 -> 64 | L32: =I32+65 -> 46124
A33: 31 | B33: 34 | C33: =LOOKUP(A33,ADQUISICIONES!R47:R93,ADQUISICIONES!Y47:Y93) -> 855.80152 | D33: =LOOKUP(A33,ADQUISICIONES!$R$17:$R$63,ADQUISICIONES!$T$17:$T$63) -> 10616 | E33: FALSE | F33: =(C33*18%) -> 154.04427 | G33: CN119698666JP | H33: TRUE | I33: 46059 | J33: 46123 | K33: =J33-I33 -> 64 | L33: =I33+65 -> 46124
A34: 32 | B34: 35 | C34: =LOOKUP(A34,ADQUISICIONES!R48:R94,ADQUISICIONES!Y47:Y94) -> 855.80152 | D34: =LOOKUP(A34,ADQUISICIONES!$R$17:$R$63,ADQUISICIONES!$T$17:$T$63) -> 15454 | E34: FALSE | F34: =(C34*18%) -> 154.04427 | G34: CN119981135JP | H34: TRUE | I34: 46062 | J34: 46147 | K34: =J34-I34 -> 85 | L34: =I34+65 -> 46127
A35: 33 | B35: 36 | C35: =LOOKUP(A35,ADQUISICIONES!R49:R95,ADQUISICIONES!Y48:Y95) -> 1173.4819 | D35: =LOOKUP(A35,ADQUISICIONES!$R$17:$R$63,ADQUISICIONES!$T$17:$T$63) -> 1294 | E35: TRUE | F35: =(C35*18%) -> 211.22674 | G35: CN119922429JP | H35: TRUE | I35: 46062 | J35: 46148 | K35: =J35-I35 -> 86 | L35: =I35+65 -> 46127
A36: 34 | B36: 37 | C36: =LOOKUP(A36,ADQUISICIONES!R50:R96,ADQUISICIONES!Y49:Y96) -> 814.91443 | D36: =LOOKUP(A36,ADQUISICIONES!$R$17:$R$63,ADQUISICIONES!$T$17:$T$63) -> 16204 | E36: FALSE | F36: =(C36*18%) -> 146.6846 | G36: CN119869895JP | H36: TRUE | I36: 46062 | J36: 46147 | K36: =J36-I36 -> 85 | L36: =I36+65 -> 46127
A37: 35 | B37: 38 | C37: =LOOKUP(A37,ADQUISICIONES!R51:R97,ADQUISICIONES!Y50:Y97) -> 944.4486 | D37: =LOOKUP(A37,ADQUISICIONES!$R$17:$R$63,ADQUISICIONES!$T$17:$T$63) -> 14420 | E37: FALSE | F37: =(C37*18%) -> 170.00075 | G37: CN120269559JP | H37: TRUE | I37: 46063 | J37: 46147 | K37: =J37-I37 -> 84 | L37: =I37+65 -> 46128
A38: 36 | B38: 39 | C38: =LOOKUP(A38,ADQUISICIONES!R52:R98,ADQUISICIONES!Y51:Y98) -> 1292.4433 | D38: =LOOKUP(A38,ADQUISICIONES!$R$17:$R$63,ADQUISICIONES!$T$17:$T$63) -> 17690 | E38: TRUE | F38: =(C38*18%) -> 232.6398 | G38: CN120489311JP | H38: TRUE | I38: 46063 | J38: 46147 | K38: =J38-I38 -> 84 | L38: =I38+65 -> 46128
A39: 37 | B39: 40 | C39: =LOOKUP(A39,ADQUISICIONES!R53:R99,ADQUISICIONES!Y52:Y99) -> 1177.1712 | E39: FALSE | F39: =(C39*18%) -> 211.89081 | G39: CN120179354JP | H39: TRUE | I39: 46066 | J39: 46147 | K39: =J39-I39 -> 81 | L39: =I39+65 -> 46131 | N39: 46220
A40: 38 | B40: 41 | C40: =LOOKUP(A40,ADQUISICIONES!R54:R100,ADQUISICIONES!Y53:Y100) -> 1065.1232 | E40: FALSE | F40: =(C40*18%) -> 191.72218 | G40: CN126224895JP | H40: FALSE | I40: 46154 | K40: =$K$1-I40 -> 49 | L40: =I40+65 -> 46219 | M40: FAB | N40: =$N$39-L40 -> 1
...

Sheet ADQUISICIONES
A1: LA TIENDITA DE BLUE | R1: CALCULADORA | X1: HORAS | Y1: MINUTOS
A2: MES | B2: TIPO | C2: LOTE | D2: PESO | E2: COMISION | F2: COSTO | G2: ENVIO NAC | H2: TOTAL | I2: ENVIO INT | J2: E INT SOL | K2: SOLES | L2: (+SUNAT) | M2: APROX | N2: REVENUE | O2: N° CAJA | P2: N ENVIO | R2: TIPO DE CAMBIO | T2: =AD4 -> 0.024246429 | U2: 24000 | V2: =(U2*T2)*111.5% -> 648.83443 | W2: =(U2/T3)*111.5% -> 235.97541 | X2: 20 | Y2: 20
A3: DICIEMBRE | B3: JUNK | C3: 1 | D3: 18400 | E3: 1000 | F3: 25500 | G3: 1780 | H3: =SUM(E3:G3) -> 28280 | I3: =(LOOKUP(O3,$R$16:$R$27,$X$16:$X$27)*D3)/LOOKUP(O3,$R$16:$R$27,$T$16:$T$27) -> 15342.466 | J3: =I3*$T$2 -> 372 | K3: =(H3*$T$2)+(I3*$T$2) -> 1057.689 | L3: =(LOOKUP(O3,$R$16:$R$27,$Z$16:$Z$27)*F3)/LOOKUP(O3,$R$16:$R$27,$U$16:$U$27)+K3 -> 1356.2886 | M3: 3000 | N3: =M3-L3 -> 1643.7114 | O3: 1 | P3: 1 | T3: =AE3 -> 113.40164 | V3: SOLES | W3: DOLARES | AC3: 28000 | AD3: 246.91 | AE3: =AC3/AD3 -> 113.40164
A4: DICIEMBRE | B4: JUNK | C4: 4 | D4: 352 | E4: 1000 | F4: 12 | G4: 990 | H4: =SUM(E4:G4) -> 2002 | I4: =(LOOKUP(O4,$R$16:$R$27,$X$16:$X$27)*D4)/LOOKUP(O4,$R$16:$R$27,$T$16:$T$27) -> 293.50804 | J4: =I4*$T$2 -> 7.1165217 | K4: =(H4*$T$2)+(I4*$T$2) -> 55.657872 | L4: =(LOOKUP(O4,$R$16:$R$27,$Z$16:$Z$27)*F4)/LOOKUP(O4,$R$16:$R$27,$U$16:$U$27)+K4 -> 55.798389 | M4: 100 | N4: =M4-L4 -> 44.201611 | O4: 1 | P4: 1 | R4: COSTO COMPRA | S4: =SUM(F:F) -> 1576737 | T4: =$T$2*S4 -> 38230.241 | W4: LIMITE | AC4: 678.9 | AD4: =AC4/AC3 -> 0.024246429
A5: DICIEMBRE | B5: NEW | C5: 5 | D5: 402 | E5: 1000 | F5: 1 | G5: 3350 | H5: =SUM(E5:G5) -> 4351 | I5: =(LOOKUP(O5,$R$16:$R$27,$X$16:$X$27)*D5)/LOOKUP(O5,$R$16:$R$27,$T$16:$T$27) -> 335.19952 | J5: =I5*$T$2 -> 8.1273913 | K5: =(H5*$T$2)+(I5*$T$2) -> 113.6236 | L5: =(LOOKUP(O5,$R$16:$R$27,$Z$16:$Z$27)*F5)/LOOKUP(O5,$R$16:$R$27,$U$16:$U$27)+K5 -> 113.63531 | M5: 60 | N5: =M5-L5 -> -53.635312 | O5: 1 | P5: 1 | R5: ENVIO NAC | S5: =SUM(G:G) -> 147724 | T5: =$T$2*S5 -> 3581.7794 | W5: =NOW()+(2/24)+((X2/24))+(Y2/1440) -> 46204.845
A6: DICIEMBRE | B6: NEW | C6: 14 | D6: 470 | E6: 1000 | F6: 1 | G6: 3800 | H6: =SUM(E6:G6) -> 4801 | I6: =(LOOKUP(O6,$R$16:$R$27,$X$16:$X$27)*D6)/LOOKUP(O6,$R$16:$R$27,$T$16:$T$27) -> 391.89994 | J6: =I6*$T$2 -> 9.5021739 | K6: =(H6*$T$2)+(I6*$T$2) -> 125.90928 | L6: =(LOOKUP(O6,$R$16:$R$27,$Z$16:$Z$27)*F6)/LOOKUP(O6,$R$16:$R$27,$U$16:$U$27)+K6 -> 125.92099 | M6: 55 | N6: =M6-L6 -> -70.920987 | O6: 1 | P6: 1 | R6: ENVIO INT | S6: =SUM(I:I) -> 662748.47 | T6: =$T$2*S6 -> 16069.283
A7: DICIEMBRE | B7: NEW | C7: 26 | D7: 524 | E7: 500 | F7: 1500 | G7: 0 | H7: =SUM(E7:G7) -> 2000 | I7: =(LOOKUP(O7,$R$16:$R$27,$X$16:$X$27)*D7)/LOOKUP(O7,$R$16:$R$27,$T$16:$T$27) -> 436.92674 | J7: =I7*$T$2 -> 10.593913 | K7: =(H7*$T$2)+(I7*$T$2) -> 59.08677 | L7: =(LOOKUP(O7,$R$16:$R$27,$Z$16:$Z$27)*F7)/LOOKUP(O7,$R$16:$R$27,$U$16:$U$27)+K7 -> 76.651454 | M7: 100 | N7: =M7-L7 -> 23.348546 | O7: 1 | P7: 1 | R7: COMISION | S7: =SUM(E:E) -> 119800 | T7: =$T$2*S7 -> 2904.7221
A8: DICIEMBRE | B8: JUNK | C8: 20 | D8: 1826 | E8: 1000 | F8: 5165 | G8: 880 | H8: =SUM(E8:G8) -> 7045 | I8: =(LOOKUP(O8,$R$16:$R$27,$X$16:$X$27)*D8)/LOOKUP(O8,$R$16:$R$27,$T$16:$T$27) -> 1522.1741 | J8: =I8*$T$2 -> 36.907285 | K8: =(H8*$T$2)+(I8*$T$2) -> 207.72337 | L8: =(LOOKUP(O8,$R$16:$R$27,$Z$16:$Z$27)*F8)/LOOKUP(O8,$R$16:$R$27,$U$16:$U$27)+K8 -> 257.79661 | M8: 200 | N8: =M8-L8 -> -57.79661 | O8: 2 | P8: 2 | R8: SUBTOTALES | S8: =SUM(H:H)+M1 -> 1844261 | T8: =$T$2*S8 -> 44716.743
A9: DICIEMBRE | B9: GACHA | C9: 21 | D9: 914 | E9: 500 | F9: 7763 | G9: 880 | H9: =SUM(E9:G9) -> 9143 | I9: =(LOOKUP(O9,$R$16:$R$27,$X$16:$X$27)*D9)/LOOKUP(O9,$R$16:$R$27,$T$16:$T$27) -> 761.92064 | J9: =I9*$T$2 -> 18.473854 | K9: =(H9*$T$2)+(I9*$T$2) -> 240.15895 | L9: =(LOOKUP(O9,$R$16:$R$27,$Z$16:$Z$27)*F9)/LOOKUP(O9,$R$16:$R$27,$U$16:$U$27)+K9 -> 315.41907 | M9: 600 | N9: =M9-L9 -> 284.58093 | O9: 2 | P9: 2 | T9: =SUM(K:K) -> 60786.026 | W9: PERDIDA | X9: =SUMIF(N:N,"<0") -> -10240.152
A10: DICIEMBRE | B10: JUNK | C10: 24 | D10: 13350 | E10: 1000 | F10: 11200 | G10: 1970 | H10: =SUM(E10:G10) -> 14170 | I10: =(LOOKUP(O10,$R$16:$R$27,$X$16:$X$27)*D10)/LOOKUP(O10,$R$16:$R$27,$T$16:$T$27) -> 11128.71 | J10: =I10*$T$2 -> 269.83146 | K10: =(H10*$T$2)+(I10*$T$2) -> 613.40335 | L10: =(LOOKUP(O10,$R$16:$R$27,$Z$16:$Z$27)*F10)/LOOKUP(O10,$R$16:$R$27,$U$16:$U$27)+K10 -> 721.98423 | M10: 1500 | N10: =M10-L10 -> 778.01577 | O10: 2 | P10: 2 | S10: PRECIO APROX | T10: =SUM(M:M) -> 94691.026
A11: DICIEMBRE | B11: NEW | C11: 29 | D11: 1904 | E11: 1000 | F11: 4200 | G11: 0 | H11: =SUM(E11:G11) -> 5200 | I11: =(LOOKUP(O11,$R$16:$R$27,$X$16:$X$27)*D11)/LOOKUP(O11,$R$16:$R$27,$T$16:$T$27) -> 1587.1957 | J11: =I11*$T$2 -> 38.483828 | K11: =(H11*$T$2)+(I11*$T$2) -> 164.56526 | L11: =(LOOKUP(O11,$R$16:$R$27,$Z$16:$Z$27)*F11)/LOOKUP(O11,$R$16:$R$27,$U$16:$U$27)+K11 -> 205.28309 | M11: 300 | N11: =M11-L11 -> 94.716914 | O11: 2 | P11: 2 | T11: REVENUE | U11: =SUM(M:M)-SUM(L:L) -> 22547.833
A12: DICIEMBRE | B12: JUNK | C12: 3 | D12: 12180 | E12: 1000 | F12: 14050 | G12: 0 | H12: =SUM(E12:G12) -> 15050 | I12: =(LOOKUP(O12,$R$16:$R$27,$X$16:$X$27)*D12)/LOOKUP(O12,$R$16:$R$27,$T$16:$T$27) -> 8804.8193 | J12: =I12*$T$2 -> 213.48542 | K12: =(H12*$T$2)+(I12*$T$2) -> 578.39417 | L12: =(LOOKUP(O12,$R$16:$R$27,$Z$16:$Z$27)*F12)/LOOKUP(O12,$R$16:$R$27,$U$16:$U$27)+K12 -> 578.39417 | M12: 1500 | N12: =M12-L12 -> 921.60583 | O12: 4 | P12: 3 | T12: SIN IMPUESTOS | U12: =SUM(M:M)-SUM(K:K) -> 33905
A13: DICIEMBRE | B13: JUNK | C13: 70 | D13: 6910 | E13: 500 | F13: 14780 | G13: 1500 | H13: =SUM(E13:G13) -> 16780 | I13: =(LOOKUP(O13,$R$16:$R$27,$X$16:$X$27)*D13)/LOOKUP(O13,$R$16:$R$27,$T$16:$T$27) -> 4995.1807 | J13: =I13*$T$2 -> 121.11529 | K13: =(H13*$T$2)+(I13*$T$2) -> 527.97036 | L13: =(LOOKUP(O13,$R$16:$R$27,$Z$16:$Z$27)*F13)/LOOKUP(O13,$R$16:$R$27,$U$16:$U$27)+K13 -> 527.97036 | M13: 1200 | N13: =M13-L13 -> 672.02964 | O13: 4 | P13: 3
A14: DICIEMBRE | B14: NEW | C14: 28 | D14: 5048 | E14: 1000 | F14: 6500 | G14: 1780 | H14: =SUM(E14:G14) -> 9280 | I14: =(LOOKUP(O14,$R$16:$R$27,$X$16:$X$27)*D14)/LOOKUP(O14,$R$16:$R$27,$T$16:$T$27) -> 5449.5823 | J14: =I14*$T$2 -> 132.13291 | K14: =(H14*$T$2)+(I14*$T$2) -> 357.13977 | L14: =(LOOKUP(O14,$R$16:$R$27,$Z$16:$Z$27)*F14)/LOOKUP(O14,$R$16:$R$27,$U$16:$U$27)+K14 -> 357.13977 | M14: 600 | N14: =M14-L14 -> 242.86023 | O14: 3 | P14: 5 | R14: ENVIOS
A15: DICIEMBRE | B15: NEW | C15: 30 | D15: 5030 | E15: 1000 | F15: 6250 | G15: 1780 | H15: =SUM(E15:G15) -> 9030 | I15: =(LOOKUP(O15,$R$16:$R$27,$X$16:$X$27)*D15)/LOOKUP(O15,$R$16:$R$27,$T$16:$T$27) -> 5430.1504 | J15: =I15*$T$2 -> 131.66175 | K15: =(H15*$T$2)+(I15*$T$2) -> 350.607 | L15: =(LOOKUP(O15,$R$16:$R$27,$Z$16:$Z$27)*F15)/LOOKUP(O15,$R$16:$R$27,$U$16:$U$27)+K15 -> 350.607 | M15: 600 | N15: =M15-L15 -> 249.393 | O15: 3 | P15: 5 | R15: N CAJA | T15: PESO | U15: COSTO NETO | V15: ESTADO | X15: COSTO ENVIO | Y15: COSTO BRUTO | Z15: IMPUESTO | AA15: COSTE FINAL | AB15: PROFIT
A16: DICIEMBRE | B16: NEW | C16: 34 | D16: 1640 | E16: 500 | F16: 1980 | G16: 1280 | H16: =SUM(E16:G16) -> 3760 | I16: =(LOOKUP(O16,$R$16:$R$27,$X$16:$X$27)*D16)/LOOKUP(O16,$R$16:$R$27,$T$16:$T$27) -> 1770.4665 | J16: =I16*$T$2 -> 42.92749 | K16: =(H16*$T$2)+(I16*$T$2) -> 134.09406 | L16: =(LOOKUP(O16,$R$16:$R$27,$Z$16:$Z$27)*F16)/LOOKUP(O16,$R$16:$R$27,$U$16:$U$27)+K16 -> 134.09406 | M16: 150 | N16: =M16-L16 -> 15.905939 | O16: 3 | P16: 5 | R16: 0 | T16: 1 | U16: 23200 | Y16: 601.22585 | Z16: 132.26969 | AA16: 733.49554 | AB16: 316.50446
A17: DICIEMBRE | B17: USED | C17: 35 | D17: 538 | E17: 500 | F17: 1580 | G17: 640 | H17: =SUM(E17:G17) -> 2720 | I17: =(LOOKUP(O17,$R$16:$R$27,$X$16:$X$27)*D17)/LOOKUP(O17,$R$16:$R$27,$T$16:$T$27) -> 580.79938 | J17: =I17*$T$2 -> 14.082311 | K17: =(H17*$T$2)+(I17*$T$2) -> 80.032596 | L17: =(LOOKUP(O17,$R$16:$R$27,$Z$16:$Z$27)*F17)/LOOKUP(O17,$R$16:$R$27,$U$16:$U$27)+K17 -> 80.032596 | M17: 100 | N17: =M17-L17 -> 19.967404 | O17: 3 | P17: 5 | R17: 1 | S17: 1 | T17: 20148 | U17: 27014 | X17: 16800 | Y17: 1437.8557 | Z17: 316.32825 | AA17: 1754.1839 | AB17: 1244.4878
A18: DICIEMBRE | B18: JUNK | C18: 48 | D18: 2182 | E18: 500 | F18: 2200 | G18: 1130 | H18: =SUM(E18:G18) -> 3830 | I18: =(LOOKUP(O18,$R$16:$R$27,$X$16:$X$27)*D18)/LOOKUP(O18,$R$16:$R$27,$T$16:$T$27) -> 2355.5841 | J18: =I18*$T$2 -> 57.114502 | K18: =(H18*$T$2)+(I18*$T$2) -> 149.97832 | L18: =(LOOKUP(O18,$R$16:$R$27,$Z$16:$Z$27)*F18)/LOOKUP(O18,$R$16:$R$27,$U$16:$U$27)+K18 -> 149.97832 | M18: 500 | N18: =M18-L18 -> 350.02168 | O18: 3 | P18: 5 | R18: 2 | S18: 2 | T18: 17994 | U18: 28328 | X18: 15000 | Y18: 1248.3276 | Z18: 274.63207 | AA18: 1522.9596 | AB18: 802.40829
A19: DICIEMBRE | B19: MERCH | C19: 58 | D19: 1124 | E19: 500 | F19: 1700 | G19: 230 | H19: =SUM(E19:G19) -> 2430 | I19: =(LOOKUP(O19,$R$16:$R$27,$X$16:$X$27)*D19)/LOOKUP(O19,$R$16:$R$27,$T$16:$T$27) -> 1213.4173 | J19: =I19*$T$2 -> 29.421036 | K19: =(H19*$T$2)+(I19*$T$2) -> 88.339857 | L19: =(LOOKUP(O19,$R$16:$R$27,$Z$16:$Z$27)*F19)/LOOKUP(O19,$R$16:$R$27,$U$16:$U$27)+K19 -> 88.339857 | M19: 150 | N19: =M19-L19 -> 61.660143 | O19: 3 | P19: 5 | R19: 3 | S19: 5 | T19: 15562 | U19: 20210 | X19: 16800 | Y19: 1181.4643 | Z19: 0 | AA19: 1181.4643 | AB19: 918.53565
A20: DICIEMBRE | B20: NEW | C20: 56 | D20: 384 | E20: 500 | F20: 1400 | G20: 800 | H20: =SUM(E20:G20) -> 2700 | I20: =(LOOKUP(O20,$R$16:$R$27,$X$16:$X$27)*D20)/LOOKUP(O20,$R$16:$R$27,$T$16:$T$27) -> 328.72022 | J20: =I20*$T$2 -> 7.9702913 | K20: =(H20*$T$2)+(I20*$T$2) -> 73.435648 | L20: =(LOOKUP(O20,$R$16:$R$27,$Z$16:$Z$27)*F20)/LOOKUP(O20,$R$16:$R$27,$U$16:$U$27)+K20 -> 73.435648 | M20: 60 | N20: =M20-L20 -> -13.435648 | O20: 5 | P20: 6 | R20: 4 | S20: 5 | T20: 19090 | U20: 28830 | X20: 13800 | Y20: 1126.6503 | Z20: 0 | AA20: 1126.6503 | AB20: 1573.3497
A21: DICIEMBRE | B21: NEW | C21: 88 | D21: 302 | E21: 500 | F21: 800 | G21: 0 | H21: =SUM(E21:G21) -> 1300 | I21: =(LOOKUP(O21,$R$16:$R$27,$X$16:$X$27)*D21)/LOOKUP(O21,$R$16:$R$27,$T$16:$T$27) -> 258.52475 | J21: =I21*$T$2 -> 6.268302 | K21: =(H21*$T$2)+(I21*$T$2) -> 37.788659 | L21: =(LOOKUP(O21,$R$16:$R$27,$Z$16:$Z$27)*F21)/LOOKUP(O21,$R$16:$R$27,$U$16:$U$27)+K21 -> 37.788659 | M21: 50 | N21: =M21-L21 -> 12.211341 | O21: 5 | P21: 6 | R21: 5 | S21: 6 | T21: 14018 | U21: 23500 | X21: 12000 | Y21: 1051.0959 | Z21: 0 | AA21: 1051.0959 | AB21: 658.90413
A22: DICIEMBRE | B22: NEW | C22: 89 | D22: 13270 | E22: 500 | F22: 20500 | G22: 3980 | H22: =SUM(E22:G22) -> 24980 | I22: =(LOOKUP(O22,$R$16:$R$27,$X$16:$X$27)*D22)/LOOKUP(O22,$R$16:$R$27,$T$16:$T$27) -> 11359.68 | J22: =I22*$T$2 -> 275.43168 | K22: =(H22*$T$2)+(I22*$T$2) -> 881.10747 | L22: =(LOOKUP(O22,$R$16:$R$27,$Z$16:$Z$27)*F22)/LOOKUP(O22,$R$16:$R$27,$U$16:$U$27)+K22 -> 881.10747 | M22: 1600 | N22: =M22-L22 -> 718.89253 | O22: 5 | P22: 6 | R22: 6 | S22: 7 | T22: 22836 | U22: 27350 | X22: 17400 | Y22: 1321.6399 | Z22: 0 | AA22: 1321.6399 | AB22: 928.36006
A23: DICIEMBRE | B23: DANTE | C23: 91 | D23: 62 | E23: 500 | F23: 800 | G23: 290 | H23: =SUM(E23:G23) -> 1590 | I23: =(LOOKUP(O23,$R$16:$R$27,$X$16:$X$27)*D23)/LOOKUP(O23,$R$16:$R$27,$T$16:$T$27) -> 53.074618 | J23: =I23*$T$2 -> 1.2868699 | K23: =(H23*$T$2)+(I23*$T$2) -> 39.838691 | L23: =(LOOKUP(O23,$R$16:$R$27,$Z$16:$Z$27)*F23)/LOOKUP(O23,$R$16:$R$27,$U$16:$U$27)+K23 -> 39.838691 | M23: 0 | N23: =M23-L23 -> -39.838691 | O23: 5 | P23: 6 | R23: 7 | S23: 8 | T23: 1002 | U23: 9200 | X23: 4400 | Y23: 348.1431 | Z23: 0 | AA23: 348.1431 | AB23: 0
A24: DICIEMBRE | B24: USED | C24: 65 | D24: 5830 | E24: 500 | F24: 8250 | G24: 1300 | H24: =SUM(E24:G24) -> 10050 | I24: =(LOOKUP(O24,$R$16:$R$27,$X$16:$X$27)*D24)/LOOKUP(O24,$R$16:$R$27,$T$16:$T$27) -> 4442.1965 | J24: =I24*$T$2 -> 107.7074 | K24: =(H24*$T$2)+(I24*$T$2) -> 351.38401 | L24: =(LOOKUP(O24,$R$16:$R$27,$Z$16:$Z$27)*F24)/LOOKUP(O24,$R$16:$R$27,$U$16:$U$27)+K24 -> 351.38401 | M24: 800 | N24: =M24-L24 -> 448.61599 | O24: 6 | P24: 7 | R24: 8 | S24: 10 | T24: 25918 | U24: 26559 | X24: 20400 | Y24: 1438.1026 | Z24: 316.38257 | AA24: 1754.4852 | AB24: 779.13225
A25: DICIEMBRE | B25: JUNK | C25: 69 | D25: 9368 | E25: 500 | F25: 7950 | G25: 1000 | H25: =SUM(E25:G25) -> 9450 | I25: =(LOOKUP(O25,$R$16:$R$27,$X$16:$X$27)*D25)/LOOKUP(O25,$R$16:$R$27,$T$16:$T$27) -> 7137.9926 | J25: =I25*$T$2 -> 173.07083 | K25: =(H25*$T$2)+(I25*$T$2) -> 402.19958 | L25: =(LOOKUP(O25,$R$16:$R$27,$Z$16:$Z$27)*F25)/LOOKUP(O25,$R$16:$R$27,$U$16:$U$27)+K25 -> 402.19958 | M25: 700 | N25: =M25-L25 -> 297.80042 | O25: 6 | P25: 7 | R25: 9 | S25: 14 | T25: 16178 | U25: 27759 | X25: 13200 | Y25: 1175.02 | Z25: 258.5044 | AA25: 1433.5244 | AB25: 272.9712
A26: DICIEMBRE | B26: GACHA | C26: 93 | D26: 4852 | E26: 500 | F26: 8250 | G26: 1000 | H26: =SUM(E26:G26) -> 9750 | I26: =(LOOKUP(O26,$R$16:$R$27,$X$16:$X$27)*D26)/LOOKUP(O26,$R$16:$R$27,$T$16:$T$27) -> 3697.0047 | J26: =I26*$T$2 -> 89.639161 | K26: =(H26*$T$2)+(I26*$T$2) -> 326.04184 | L26: =(LOOKUP(O26,$R$16:$R$27,$Z$16:$Z$27)*F26)/LOOKUP(O26,$R$16:$R$27,$U$16:$U$27)+K26 -> 326.04184 | M26: 450 | N26: =M26-L26 -> 123.95816 | O26: 6 | P26: 7 | R26: 10 | S26: 11 | T26: 10632 | U26: 28311 | X26: 10200 | Y26: 1053.3428 | Z26: 231.73541 | AA26: 1285.0782 | AB26: 583.18644
A27: DICIEMBRE | B27: MERCH | C27: 94 | D27: 2786 | E27: 500 | F27: 2900 | G27: 1250 | H27: =SUM(E27:G27) -> 4650 | I27: =(SUMIFS($X$16:$X$27,$R$16:$R$27,O27))/(COUNTIF(O:O,O27)) -> 4350 | J27: =I27*$T$2 -> 105.47196 | K27: =(H27*$T$2)+(I27*$T$2) -> 218.21786 | L27: =(LOOKUP(O27,$R$16:$R$27,$Z$16:$Z$27)*F27)/LOOKUP(O27,$R$16:$R$27,$U$16:$U$27)+K27 -> 218.21786 | M27: 300 | N27: =M27-L27 -> 81.782143 | O27: 6 | P27: 7 | R27: 11 | S27: 16 | T27: 10442 | U27: 28755 | X27: 9600 | Y27: 986.52891 | Z27: 217.03636 | AA27: 1203.5653 | AB27: -18.61422
A28: DICIEMBRE | B28: ROXANA | C28: 96 | D28: 1002 | E28: 500 | F28: 9200 | G28: 0 | H28: =SUM(E28:G28) -> 9700 | I28: 4400 | J28: =I28*$T$2 -> 106.68429 | K28: =(H28*$T$2)+(I28*$T$2) -> 341.87464 | L28: =(LOOKUP(O28,$R$16:$R$27,$Z$16:$Z$27)*F28)/LOOKUP(O28,$R$16:$R$27,$U$16:$U$27)+K28 -> 341.87464 | M28: =K28 -> 341.87464 | N28: =M28-L28 -> 0 | O28: 7 | P28: 8 | R28: 12 | S28: 13 | T28: 15170 | U28: 28943 | X28: 13200 | Y28: 1080.0584 | Z28: 237.61285 | AA28: 1317.6713 | AB28: -162.97883
A29: DICIEMBRE | B29: USED | C29: 98 | D29: 6404 | E29: 500 | F29: 6959 | G29: 1915 | H29: =SUM(E29:G29) -> 9374 | I29: =(LOOKUP(O29,$R$16:$R$27,$X$16:$X$27)*D29)/LOOKUP(O29,$R$16:$R$27,$T$16:$T$27) -> 5040.5741 | J29: =I29*$T$2 -> 122.21592 | K29: =(H29*$T$2)+(I29*$T$2) -> 349.50194 | L29: =(LOOKUP(O29,$R$16:$R$27,$Z$16:$Z$27)*F29)/LOOKUP(O29,$R$16:$R$27,$U$16:$U$27)+K29 -> 432.40063 | M29: 1000 | N29: =M29-L29 -> 567.59937 | O29: 8 | P29: 10 | R29: 13 | S29: 17 | T29: 14560 | U29: 28277 | X29: 13200 | Y29: 1063.6142 | Z29: 233.99513 | AA29: 1297.6093 | AB29: -0.23808072
A30: DICIEMBRE | B30: USED | C30: 100 | D30: 5810 | E30: 500 | F30: 6600 | G30: 2010 | H30: =SUM(E30:G30) -> 9110 | I30: =(LOOKUP(O30,$R$16:$R$27,$X$16:$X$27)*D30)/LOOKUP(O30,$R$16:$R$27,$T$16:$T$27) -> 4573.038 | J30: =I30*$T$2 -> 110.87984 | K30: =(H30*$T$2)+(I30*$T$2) -> 331.7648 | L30: =(LOOKUP(O30,$R$16:$R$27,$Z$16:$Z$27)*F30)/LOOKUP(O30,$R$16:$R$27,$U$16:$U$27)+K30 -> 410.38693 | M30: 750 | N30: =M30-L30 -> 339.61307 | O30: 8 | P30: 10 | R30: 14 | S30: 15 | T30: 11042 | U30: 29000 | X30: 10800 | Y30: 1041.9602 | Z30: 229.23124 | AA30: 1271.1914 | AB30: -20.698768
A31: DICIEMBRE | B31: NEW | C31: 104 | D31: 2464 | E31: 500 | F31: 4200 | G31: 1620 | H31: =SUM(E31:G31) -> 6320 | I31: =(LOOKUP(O31,$R$16:$R$27,$X$16:$X$27)*D31)/LOOKUP(O31,$R$16:$R$27,$T$16:$T$27) -> 1939.4089 | J31: =I31*$T$2 -> 47.023739 | K31: =(H31*$T$2)+(I31*$T$2) -> 200.26117 | L31: =(LOOKUP(O31,$R$16:$R$27,$Z$16:$Z$27)*F31)/LOOKUP(O31,$R$16:$R$27,$U$16:$U$27)+K31 -> 250.29343 | M31: 350 | N31: =M31-L31 -> 99.706571 | O31: 8 | P31: 10 | R31: 15 | S31: 12 | T31: 9450 | U31: 28459 | X31: 10800 | Y31: 1048.3552 | Z31: 230.63814 | AA31: 1278.9933 | AB31: 254.589
A32: DICIEMBRE | B32: USED | C32: 109 | D32: 5022 | E32: 500 | F32: 4400 | G32: 1620 | H32: =SUM(E32:G32) -> 6520 | I32: =(LOOKUP(O32,$R$16:$R$27,$X$16:$X$27)*D32)/LOOKUP(O32,$R$16:$R$27,$T$16:$T$27) -> 3952.805 | J32: =I32*$T$2 -> 95.841404 | K32: =(H32*$T$2)+(I32*$T$2) -> 253.92812 | L32: =(LOOKUP(O32,$R$16:$R$27,$Z$16:$Z$27)*F32)/LOOKUP(O32,$R$16:$R$27,$U$16:$U$27)+K32 -> 306.34287 | M32: 450 | N32: =M32-L32 -> 143.65713 | O32: 8 | P32: 10 | R32: 16 | S32: 18 | T32: 16574 | U32: 29046 | X32: 14400 | Y32: 1225.8094 | Z32: 269.67806 | AA32: 1495.4875 | AB32: 410.02293
A33: DICIEMBRE | B33: USED | C33: 111 | D33: 6218 | E33: 500 | F33: 4400 | G33: 1620 | H33: =SUM(E33:G33) -> 6520 | I33: =(LOOKUP(O33,$R$16:$R$27,$X$16:$X$27)*D33)/LOOKUP(O33,$R$16:$R$27,$T$16:$T$27) -> 4894.1739 | J33: =I33*$T$2 -> 118.66624 | K33: =(H33*$T$2)+(I33*$T$2) -> 276.75295 | L33: =(LOOKUP(O33,$R$16:$R$27,$Z$16:$Z$27)*F33)/LOOKUP(O33,$R$16:$R$27,$U$16:$U$27)+K33 -> 329.1677 | M33: 450 | N33: =M33-L33 -> 120.8323 | O33: 8 | P33: 10 | R33: 17 | S33: 19 | T33: 15602 | U33: 29449 | X33: 13200 | Y33: 1294.0306 | Z33: 284.68674 | AA33: 1578.7174 | AB33: 276.99599
A34: ENERO | B34: NEW | C34: 107 | D34: 1698 | E34: 500 | F34: 1511 | G34: 1620 | H34: =SUM(E34:G34) -> 3631 | I34: =(LOOKUP(O34,$R$16:$R$40,$X$16:$X$40)*D34)/LOOKUP(O34,$R$16:$R$40,$T$16:$T$40) -> 1629.0068 | J34: =I34*$T$2 -> 39.497596 | K34: =(H34*$T$2)+(I34*$T$2) -> 127.53638 | L34: =(LOOKUP(O34,$R$16:$R$27,$Z$16:$Z$27)*F34)/LOOKUP(O34,$R$16:$R$27,$U$16:$U$27)+K34 -> 139.90444 | M34: 300 | N34: =M34-L34 -> 160.09556 | O34: 10 | P34: 11 | R34: 18 | S34: 20 | T34: 22719 | U34: 29949 | X34: 17400 | Y34: 1393.0074 | Z34: 306.46163 | AA34: 1699.469 | AB34: 1848.3179
A35: ENERO | B35: USED | C35: 137 | D35: 8934 | E35: 500 | F35: 26800 | G35: 1530 | H35: =SUM(E35:G35) -> 28830 | I35: =(LOOKUP(O35,$R$16:$R$40,$X$16:$X$40)*D35)/LOOKUP(O35,$R$16:$R$40,$T$16:$T$40) -> 8570.9932 | J35: =I35*$T$2 -> 207.81598 | K35: =(H35*$T$2)+(I35*$T$2) -> 906.84051 | L35: =(LOOKUP(O35,$R$16:$R$27,$Z$16:$Z$27)*F35)/LOOKUP(O35,$R$16:$R$27,$U$16:$U$27)+K35 -> 1126.2079 | M35: 1800 | N35: =M35-L35 -> 673.79215 | O35: 10 | P35: 11 | R35: 19 | S35: 22 | T35: 17138 | U35: 29175 | X35: 14400 | Y35: 1159.2116 | Z35: 255.02654 | AA35: 1414.2381 | AB35: -20.450431
A36: ENERO | B36: NEW | C36: 135 | D36: 1058 | E36: 800 | F36: 5980 | G36: 0 | H36: =SUM(E36:G36) -> 6780 | I36: =(LOOKUP(O36,$R$16:$R$40,$X$16:$X$40)*D36)/LOOKUP(O36,$R$16:$R$40,$T$16:$T$40) -> 1209.1429 | J36: =I36*$T$2 -> 29.317396 | K36: =(H36*$T$2)+(I36*$T$2) -> 193.70818 | L36: =(LOOKUP(O36,$R$16:$R$27,$Z$16:$Z$27)*F36)/LOOKUP(O36,$R$16:$R$27,$U$16:$U$27)+K36 -> 238.84389 | M36: 350 | N36: =M36-L36 -> 111.15611 | O36: 15 | P36: 12 | R36: 20 | S36: 21 | T36: =SUMIFS(D:D,O:O,R36) -> 11890 | U36: =SUMIFS($F:$F,$O:$O,R36) -> 47079 | X36: 10800 | Y36: =SUMIFS(K:K,O:O,R36) -> 1491.8585 | Z36: =Y36*22% -> 328.20887 | AA36: =Y36+Z36 -> 1820.0674 | AB36: =(SUMIFS(N:N,O:O,R36))-Z36 -> 514.59078
A37: ENERO | B37: NEW | C37: 149 | D37: 3910 | E37: 800 | F37: 8500 | G37: 0 | H37: =SUM(E37:G37) -> 9300 | I37: =(LOOKUP(O37,$R$16:$R$40,$X$16:$X$40)*D37)/LOOKUP(O37,$R$16:$R$40,$T$16:$T$40) -> 4468.5714 | J37: =I37*$T$2 -> 108.3469 | K37: =(H37*$T$2)+(I37*$T$2) -> 333.83868 | L37: =(LOOKUP(O37,$R$16:$R$27,$Z$16:$Z$27)*F37)/LOOKUP(O37,$R$16:$R$27,$U$16:$U$27)+K37 -> 397.9948 | M37: 700 | N37: =M37-L37 -> 302.0052 | O37: 15 | P37: 12 | R37: 21 | S37: 23 | T37: =SUMIFS(D:D,O:O,R37) -> 17597 | U37: =SUMIFS($F:$F,$O:$O,R37) -> 27566 | X37: 13800 | Y37: =SUMIFS(K:K,O:O,R37) -> 1231.864 | Z37: =Y37*22% -> 271.01009 | AA37: =Y37+Z37 -> 1502.8741 | AB37: =(SUMIFS(N:N,O:O,R37))-Z37 -> 639.06381
A38: ENERO | B38: NEW | C38: 152 | D38: 2060 | E38: 800 | F38: 6980 | G38: 0 | H38: =SUM(E38:G38) -> 7780 | I38: =(LOOKUP(O38,$R$16:$R$40,$X$16:$X$40)*D38)/LOOKUP(O38,$R$16:$R$40,$T$16:$T$40) -> 2354.2857 | J38: =I38*$T$2 -> 57.08302 | K38: =(H38*$T$2)+(I38*$T$2) -> 245.72023 | L38: =(LOOKUP(O38,$R$16:$R$27,$Z$16:$Z$27)*F38)/LOOKUP(O38,$R$16:$R$27,$U$16:$U$27)+K38 -> 298.40373 | M38: 280 | N38: =M38-L38 -> -18.403726 | O38: 15 | P38: 12 | R38: 22 | S38: 23 | T38: =SUMIFS(D:D,O:O,R38) -> 14436 | U38: =SUMIFS($F:$F,$O:$O,R38) -> 29999 | X38: 12600 | Y38: =SUMIFS(K:K,O:O,R38) -> 1146.1044 | Z38: =Y38*22% -> 252.14298 | AA38: =Y38+Z38 -> 1398.2474 | AB38: =(SUMIFS(N:N,O:O,R38))-Z38 -> 310.3268
A39: ENERO | B39: NEW | C39: 156 | D39: 2422 | E39: 800 | F39: 6999 | G39: 0 | H39: =SUM(E39:G39) -> 7799 | I39: =(LOOKUP(O39,$R$16:$R$40,$X$16:$X$40)*D39)/LOOKUP(O39,$R$16:$R$40,$T$16:$T$40) -> 2768 | J39: =I39*$T$2 -> 67.114114 | K39: =(H39*$T$2)+(I39*$T$2) -> 256.21201 | L39: =(LOOKUP(O39,$R$16:$R$27,$Z$16:$Z$27)*F39)/LOOKUP(O39,$R$16:$R$27,$U$16:$U$27)+K39 -> 309.03891 | M39: 400 | N39: =M39-L39 -> 90.96109 | O39: 15 | P39: 12 | R39: 23 | S39: 25 | T39: =SUMIFS(D:D,O:O,R39) -> 25978 | U39: =SUMIFS($F:$F,$O:$O,R39) -> 63829 | X39: 24600 | Y39: =SUMIFS(K:K,O:O,R39) -> 2390.4311 | Z39: =Y39*22% -> 525.89485 | AA39: =Y39+Z39 -> 2916.326 | AB39: =(SUMIFS(N:N,O:O,R39))-Z39 -> 301.90687
A40: ENERO | B40: NEW | C40: 126 | D40: 14120 | E40: 800 | F40: 24444 | G40: 0 | H40: =SUM(E40:G40) -> 25244 | I40: =(LOOKUP(O40,$R$16:$R$40,$X$16:$X$40)*D40)/LOOKUP(O40,$R$16:$R$40,$T$16:$T$40) -> 12286.355 | J40: =I40*$T$2 -> 297.90022 | K40: =(H40*$T$2)+(I40*$T$2) -> 909.97706 | L40: =(LOOKUP(O40,$R$16:$R$27,$Z$16:$Z$27)*F40)/LOOKUP(O40,$R$16:$R$27,$U$16:$U$27)+K40 -> 1094.475 | M40: 1300 | N40: =M40-L40 -> 205.52505 | O40: 12 | P40: 13 | R40: 24 | S40: 27 | T40: =SUMIFS(D:D,O:O,R40) -> 17922 | U40: =SUMIFS($F:$F,$O:$O,R40) -> 29929 | X40: 16200 | Y40: =SUMIFS(K:K,O:O,R40) -> 1329.8924 | Z40: =Y40*22% -> 292.57632 | AA40: =Y40+Z40 -> 1622.4687 | AB40: =(SUMIFS(N:N,O:O,R40))-Z40 -> 781.63387
...

Sheet Hoja 5
F3: <
E4: 2 o mas figuras | F4: 100 | G4: 5 | H4: =F4-(G4*F4) % -> 95
F5: 200 | G5: 7.5 | H5: =F5-(G5*F5) % -> 185
F6: 700 | G6: 10 | H6: =F6-(G6*F6) % -> 630

Sheet CUENTAS 2025
B1: CUENTAS | D1: SUBTOTAL | E1: 3223.99 | N1: Hola buenas hermano(a/e) tienes una cuentita pendiente:
A2: FECHA | B2: CLIENTE | C2: FIGURA | D2: MES | E2: LOTE | F2: PRECIO | G2: ADELANTO | H2: RESTANTE | I2: ENTREGADO | J2: TIPO DE ENTR | K2: FECHA LIMITE | L2: ALMACEN | O2: PAGADO | P2: =SUM(G:G) -> 24977.3 | Q2: =SUM(H2:H950) -> 5407.99
A3: 45988 | B3: DAN | C3: RIFA MERCH TOALLA CHOPPER | D3: STOCK | E3: 0 | F3: 5 | G3: 5 | H3: =F3-G3 -> 0 | I3: TRUE | J3: PENDIENTE | K3: =A3+15 -> 46003 | L3: =A3+30 -> 46018
A4: 46017 | B4: ALPHONSE | C4: CHIBI PELIAZUL | D4: MARZO | E4: 232 | F4: 20 | G4: 20 | H4: =F4-G4 -> 0 | I4: FALSE | J4: PREVENTA | K4: =A4+15 -> 46032 | L4: =A4+30 -> 46047
A5: 46017 | B5: ALPHONSE | C5: GLITTER EN TANGA | D5: ABRIL | E5: 999 | F5: 65 | G5: 65 | H5: =F5-G5 -> 0 | I5: FALSE | J5: PREVENTA | K5: =A5+15 -> 46032 | L5: =A5+30 -> 46047
A6: 45987 | B6: BUBUN | C6: 2 LLAVEROS | D6: STOCK | E6: 0 | F6: 6 | G6: 6 | H6: =F6-G6 -> 0 | I6: TRUE | J6: PENDIENTE | K6: =A6+15 -> 46002 | L6: =A6+30 -> 46017
A7: 46017 | B7: ALPHONSE | C7: GLITTER TO LOVE RU | D7: STOCK | E7: 0 | F7: 65 | G7: 65 | H7: =F7-G7 -> 0 | I7: FALSE | J7: PENDIENTE | K7: =A7+15 -> 46032 | L7: =A7+30 -> 46047
A8: 45980 | B8: JOSE ANDRE | C8: 2.5 DIMEN X2 | D8: STOCK | E8: 0 | F8: 110 | G8: 110 | H8: =F8-G8 -> 0 | I8: TRUE | J8: TREINTA | K8: =A8+15 -> 45995 | L8: =A8+30 -> 46010
A9: 45997 | B9: ARANCIEA | C9: 2.5 MIRIEL CORAZON | D9: STOCK | E9: 0 | F9: 55 | G9: 55 | H9: =F9-G9 -> 0 | I9: TRUE | J9: PENDIENTE | K9: =A9+15 -> 46012 | L9: =A9+30 -> 46027
A10: 46017 | B10: ALPHONSE | C10: UNIFORM PERU | D10: FEBRERO | E10: 174 | F10: 50 | G10: 50 | H10: =F10-G10 -> 0 | I10: FALSE | J10: PENDIENTE | K10: =A10+15 -> 46032 | L10: =A10+30 -> 46047
A11: 45954 | B11: RENZO | C11: 3 ALMIRANTES | D11: ENERO | E11: 0 | F11: 165 | G11: 165 | H11: =F11-G11 -> 0 | I11: TRUE | J11: PENDIENTE | K11: =A11+15 -> 45969 | L11: =A11+30 -> 45984
A12: 46001 | B12: BUBUN | C12: 3 PINES + MINIFILE | D12: STOCK | E12: 0 | F12: 13 | G12: 13 | H12: =F12-G12 -> 0 | I12: TRUE | J12: PENDIENTE | K12: =A12+15 -> 46016 | L12: =A12+30 -> 46031
A13: 45933 | B13: UKU | C13: 3 SELLADOS+CUADRO | D13: STOCK | F13: 185 | G13: 185 | H13: =F13-G13 -> 0 | I13: TRUE | J13: PENDIENTE | K13: =A13+15 -> 45948 | L13: =A13+30 -> 45963
A14: 45915 | B14: HUGO | C14: 3 SIN BASE | D14: STOCK | E14: 0 | F14: 60 | G14: 60 | H14: =F14-G14 -> 0 | I14: TRUE | J14: PENDIENTE | K14: =A14+15 -> 45930 | L14: =A14+30 -> 45945
A15: 46021 | B15: ALPHONSE | C15: BOLSA POKEMON | D15: STOCK | E15: 0 | F15: 10 | G15: 10 | H15: =F15-G15 -> 0 | I15: FALSE | J15: PENDIENTE | K15: =A15+15 -> 46036 | L15: =A15+30 -> 46051
A16: 46010 | B16: ARGONAUTA | C16: 4 CHIBIS MONOGATARI | D16: STOCK | E16: 0 | F16: 143.5 | G16: 143.5 | H16: =F16-G16 -> 0 | I16: TRUE | J16: PENDIENTE | K16: =A16+15 -> 46025 | L16: =A16+30 -> 46040
A17: 46021 | B17: ALPHONSE | C17: POSTER SAO | D17: STOCK | E17: 0 | F17: 15 | G17: 15 | H17: =F17-G17 -> 0 | I17: FALSE | J17: PENDIENTE | K17: =A17+15 -> 46036 | L17: =A17+30 -> 46051
A18: 45993 | B18: ARANCIEA | C18: 7 LLAVEROS | D18: STOCK | E18: 0 | F18: 21 | G18: 21 | H18: =F18-G18 -> 0 | I18: TRUE | J18: PENDIENTE | K18: =A18+15 -> 46008 | L18: =A18+30 -> 46023
A19: 45971 | B19: CHRISTIAN CONTRERAS | C19: ACE ENDEAVOR GOYO CAJA | D19: STOCK | E19: 0 | F19: 175 | G19: 175 | H19: =F19-G19 -> 0 | I19: TRUE | J19: PENDIENTE | K19: =A19+15 -> 45986 | L19: =A19+30 -> 46001
A20: 45980 | B20: DAN | C20: ACE GRANDE | D20: STOCK | E20: 0 | F20: 50 | G20: 50 | H20: =F20-G20 -> 0 | I20: TRUE | J20: PENDIENTE | K20: =A20+15 -> 45995 | L20: =A20+30 -> 46010
A21: 45981 | B21: VD | C21: ACE SIN BASE | D21: STOCK | E21: 0 | F21: 20 | G21: 20 | H21: =F21-G21 -> 0 | I21: TRUE | J21: PENDIENTE | K21: =A21+15 -> 45996 | L21: =A21+30 -> 46011
A22: 45945 | B22: ANTHONY | C22: PELUCHE TORCHIK | D22: FEBRERO | E22: 186 | F22: 30 | G22: 15 | H22: =F22-G22 -> 15 | I22: FALSE | J22: PENDIENTE | K22: =A22+15 -> 45960 | L22: =A22+30 -> 45975
A23: 45953 | B23: ANTHONY | C23: PELUCHE TOTODILE | D23: FEBRERO | E23: 186 | F23: 45 | G23: 15 | H23: =F23-G23 -> 30 | I23: FALSE | J23: PENDIENTE | K23: =A23+15 -> 45968 | L23: =A23+30 -> 45983
A24: 45997 | B24: ARANCIEA | C24: PELUCHE MORENO | D24: ABRIL | E24: 326 | F24: 90 | G24: 25 | H24: =F24-G24 -> 65 | I24: FALSE | J24: PREVENTA | K24: =A24+15 -> 46012 | L24: =A24+30 -> 46027
A25: 45959 | B25: CLEO | C25: AIN | D25: STOCK | E25: 0 | F25: 39 | G25: 39 | H25: =F25-G25 -> 0 | I25: TRUE | J25: PENDIENTE | K25: =A25+15 -> 45974 | L25: =A25+30 -> 45989
... A33: 45971 | B33: JORGEPEDRO | C33: ANYA CHIQUI | D33: STOCK | E33: 0 | F33: 23 | G33: 23 | H33: =F33-G33 -> 0 | I33: TRUE | J33: PENDIENTE | K33: =A33+15 -> 45986 | L33: =A33+30 -> 46001
A34: 45924 | B34: MARSHALL | C34: ANYA QPOSKET | D34: STOCK | F34: 21 | G34: 21 | H34: =F34-G34 -> 0 | I34: TRUE | J34: PENDIENTE | K34: =A34+15 -> 45939 | L34: =A34+30 -> 45954
A35: 46021 | B35: ARMILENK | C35: CABALLA PLOMA | D35: ABRIL | E35: 301 | F35: 85 | G35: 85 | H35: =F35-G35 -> 0 | I35: FALSE | J35: PENDIENTE | K35: =A35+15 -> 46036 | L35: =A35+30 -> 46051
A36: 45939 | B36: BASTOFORD | C36: NESUKO GLITTER | D36: STOCK | E36: 0 | F36: 48 | G36: 48 | H36: =F36-G36 -> 0 | I36: FALSE | J36: PENDIENTE | K36: =A36+15 -> 45954 | L36: =A36+30 -> 45969
A37: 45930 | B37: TROUBLE | C37: AZUNA | D37: STOCK | F37: 40 | G37: 40 | H37: =F37-G37 -> 0 | I37: TRUE | J37: PENDIENTE | K37: =A37+15 -> 45945 | L37: =A37+30 -> 45960
A38: 45966 | B38: KIWI | C38: BAKUGO | D38: STOCK | E38: 0 | F38: 45 | G38: 45 | H38: =F38-G38 -> 0 | I38: TRUE | J38: PENDIENTE | K38: =A38+15 -> 45981 | L38: =A38+30 -> 45996
A39: 46014 | B39: DAASH | C39: DEKU SENTADO | D39: MARZO | E39: 223 | F39: 50 | G39: 25 | H39: =F39-G39 -> 25 | I39: FALSE | J39: PREVENTA | K39: =A39+15 -> 46029 | L39: =A39+30 -> 46044
A40: 45965 | B40: DAN | C40: TETONA MAID | D40: MARZO | E40: 240 | F40: 90 | G40: 90 | H40: =F40-G40 -> 0 | I40: FALSE | J40: PREVENTA | K40: =A40+15 -> 45980 | L40: =A40+30 -> 45995
A41: 46021 | B41: DAVID | C41: FILE URARAKA | D41: STOCK | E41: 0 | F41: 5 | G41: 5 | H41: =F41-G41 -> 0 | I41: FALSE | J41: PENDIENTE | K41: =A41+15 -> 46036 | L41: =A41+30 -> 46051
A42: 46021 | B42: DEMONSLAYERPE | C42: GENYA POSTER | D42: STOCK | E42: 0 | F42: 5 | G42: 5 | H42: =F42-G42 -> 0 | I42: FALSE | J42: PENDIENTE | K42: =A42+15 -> 46036 | L42: =A42+30 -> 46051
A43: 45945 | B43: KIWI | C43: BARBABLANCA GRAND | D43: ENERO | E43: 0 | F43: 75 | G43: 75 | H43: =F43-G43 -> 0 | I43: TRUE | J43: PENDIENTE | K43: =A43+15 -> 45960 | L43: =A43+30 -> 45975
A44: 46001 | B44: LUIS DIAZ | C44: BARBABLANCA GRANDISTA | D44: STOCK | E44: 0 | F44: 40 | G44: 40 | H44: =F44-G44 -> 0 | I44: TRUE | J44: PENDIENTE | K44: =A44+15 -> 46016 | L44: =A44+30 -> 46031
A45: 45985 | B45: DIXON | C45: BARBABLANCA MANHOOD | D45: STOCK | E45: 0 | F45: 45 | G45: 45 | H45: =F45-G45 -> 0 | I45: TRUE | J45: PENDIENTE | K45: =A45+15 -> 46000 | L45: =A45+30 -> 46015
A46: 46009 | B46: KAEL | C46: BARDOK | D46: STOCK | E46: 0 | F46: 52 | G46: 52 | H46: =F46-G46 -> 0 | I46: TRUE | J46: PENDIENTE | K46: =A46+15 -> 46024 | L46: =A46+30 -> 46039
A47: 45915 | B47: SHOHAI | C47: BATTLE REC LUFFY | D47: STOCK | E47: 0 | F47: 55 | G47: 55 | H47: =F47-G47 -> 0 | I47: TRUE | J47: PENDIENTE | K47: =A47+15 -> 45930 | L47: =A47+30 -> 45945
...

Sheet CUENTAS 2026
B1: CUENTAS | D1: TOTALSUB | E1: 3223.99
A2: FECHA | B2: CLIENTE | C2: FIGURA | D2: MES | E2: LOTE | F2: PRECIO | G2: ADELANTO | H2: RESTANTE | I2: ENTREGADO | J2: TIPO DE ENTR | K2: FECHA LIMITE | L2: ALMACEN | M2: BASE
A3: 46124 | B3: 17JEAN | C3: REI NEGRA | D3: STOCK | E3: REMATE | F3: 30 | G3: 30 | H3: =F3-G3 -> 0 | I3: FALSE | J3: PENDIENTE | K3: =A3+15 -> 46139 | L3: =A3+30 -> 46154 | M3: FALSE
A4: 46124 | B4: 17JEAN | C4: DUO G5 V LUCCI + ICHIBAN | D4: STOCK | E4: 0 | F4: 180 | G4: 180 | H4: =F4-G4 -> 0 | I4: FALSE | J4: PENDIENTE | K4: =A4+15 -> 46139 | L4: =A4+30 -> 46154 | M4: FALSE
A5: 46052 | B5: A | C5: SHANKS+LAW GRAND | D5: STOCK | E5: 0 | F5: 120 | G5: 120 | H5: =F5-G5 -> 0 | I5: TRUE | J5: PENDIENTE | K5: =A5+15 -> 46067 | L5: =A5+30 -> 46082
A6: 46196 | B6: AARON | C6: GOJO CAMISA BLANCA + FERN SENTADA + REM CHIQUITA | D6: STOCK | E6: CAJA | F6: 170 | G6: 30 | H6: =F6-G6 -> 140 | I6: FALSE | J6: PENDIENTE | K6: =A6+15 -> 46211 | L6: =A6+30 -> 46226
A7: 46146 | B7: ADRIAN | C7: SHIGARAKI CAJA | D7: STOCK | E7: 0 | F7: 55 | G7: 55 | H7: =F7-G7 -> 0 | I7: TRUE | J7: PENDIENTE | K7: =A7+15 -> 46161 | L7: =A7+30 -> 46176
A8: 46147 | B8: ADRIAN | C8: CELL | D8: STOCK | E8: CAJA | F8: 60 | G8: 60 | H8: =F8-G8 -> 0 | I8: TRUE | J8: PENDIENTE | K8: =A8+15 -> 46162 | L8: =A8+30 -> 46177
A9: 46023 | B9: AGOS | C9: LUMINASTA CHICA HIELO | D9: AGOSTO | E9: 473 | F9: 40 | G9: 0 | H9: =F9-G9 -> 40 | I9: FALSE | J9: PENDIENTE
A10: 46135 | B10: AGOS | C10: BARBA BLANCA SIN ARMA | D10: STOCK | E10: REMATE | F10: 20 | G10: 20 | H10: =F10-G10 -> 0 | I10: TRUE | J10: PENDIENTE | K10: =A10+15 -> 46150 | L10: =A10+30 -> 46165 | M10: FALSE
A11: 46135 | B11: AGOS | C11: ANYA QPOSKET | D11: STOCK | E11: REMATE | F11: 10 | G11: 10 | H11: =F11-G11 -> 0 | I11: TRUE | J11: PENDIENTE | K11: =A11+15 -> 46150 | L11: =A11+30 -> 46165 | M11: FALSE
A12: 46135 | B12: AGOS | C12: REM VESTIDO | D12: STOCK | E12: REMATE | F12: 34 | G12: 34 | H12: =F12-G12 -> 0 | I12: TRUE | J12: PENDIENTE | K12: =A12+15 -> 46150 | L12: =A12+30 -> 46165 | M12: TRUE
A13: 46166 | B13: AGOS | C13: NICO LOVELIVE | D13: STOCK | E13: SUELTA | F13: 43 | G13: 43 | H13: =F13-G13 -> 0 | I13: FALSE | J13: PENDIENTE | K13: =A13+15 -> 46181 | L13: =A13+30 -> 46196 | M13: QUINCENA -19
A14: 46166 | B14: AGOS | C14: CONEJA BLANCA | D14: STOCK | E14: CAJA | F14: 56 | G14: 56 | H14: =F14-G14 -> 0 | I14: FALSE | J14: PENDIENTE | K14: =A14+15 -> 46181 | L14: =A14+30 -> 46196 | M14: QUINCENA -19
A15: 46187 | B15: AGOS | C15: MERCURI | D15: STOCK | E15: SUELTA | F15: 40 | G15: 40 | H15: =F15-G15 -> 0 | I15: FALSE | J15: PENDIENTE | K15: =A15+15 -> 46202 | L15: =A15+30 -> 46217
A16: 46187 | B16: AGOS | C16: ROBOT EQUUUX | D16: STOCK | E16: CAJA | F16: 60 | G16: 1 | H16: =F16-G16 -> 59 | I16: FALSE | J16: PENDIENTE | K16: =A16+15 -> 46202 | L16: =A16+30 -> 46217
A17: 46190 | B17: AGOS | C17: CONEJA TRILLIZAS | D17: STOCK | E17: SUELTA | F17: 33 | G17: 0 | H17: =F17-G17 -> 33 | I17: FALSE | J17: PENDIENTE | K17: =A17+15 -> 46205 | L17: =A17+30 -> 46220
A18: 46192 | B18: AGOS | C18: RELAX MORADA HOLO | D18: STOCK | E18: CAJA | F18: 56 | G18: 0 | H18: =F18-G18 -> 56 | I18: FALSE | J18: PENDIENTE | K18: =A18+15 -> 46207 | L18: =A18+30 -> 46222
A19: 46192 | B19: AGOS | C19: CONEJA HERMANA ALBINA | D19: STOCK | E19: CAJA | F19: 62 | G19: 0 | H19: =F19-G19 -> 62 | I19: FALSE | J19: PENDIENTE | K19: =A19+15 -> 46207 | L19: =A19+30 -> 46222
A20: 46124 | B20: AGOS | C20: GUERRERA PELIVERDE | D20: STOCK | E20: REMATE | F20: 15 | G20: 15 | H20: =F20-G20 -> 0 | I20: TRUE | J20: PENDIENTE | K20: =A20+15 -> 46139 | L20: =A20+30 -> 46154 | M20: FALSE
A21: 46124 | B21: AGOS | C21: NIKKE GATITA | D21: STOCK | E21: REMATE | F21: 25 | G21: 25 | H21: =F21-G21 -> 0 | I21: TRUE | J21: PENDIENTE | K21: =A21+15 -> 46139 | L21: =A21+30 -> 46154 | M21: FALSE
A22: 46124 | B22: AGOS | C22: RUBIA GUNDAM | D22: STOCK | E22: REMATE | F22: 29 | G22: 29 | H22: =F22-G22 -> 0 | I22: TRUE | J22: PENDIENTE | K22: =A22+15 -> 46139 | L22: =A22+30 -> 46154 | M22: TRUE
A23: 46124 | B23: AGOS | C23: MADOKA SIN MANO | D23: STOCK | E23: REMATE | F23: 15 | G23: 15 | H23: =F23-G23 -> 0 | I23: TRUE | J23: PENDIENTE | K23: =A23+15 -> 46139 | L23: =A23+30 -> 46154 | M23: FALSE
A24: 46124 | B24: AGOS | C24: RLOVELIVE | D24: STOCK | E24: REMATE | F24: 25 | G24: 25 | H24: =F24-G24 -> 0 | I24: TRUE | J24: PENDIENTE | K24: =A24+15 -> 46139 | L24: =A24+30 -> 46154 | M24: FALSE
A25: 46124 | B25: AGOS | C25: LOVELIVEPELIMORADA | D25: STOCK | E25: REMATE | F25: 24 | G25: 24 | H25: =F25-G25 -> 0 | I25: TRUE | J25: PENDIENTE | K25: =A25+15 -> 46139 | L25: =A25+30 -> 46154 | M25: TRUE
A26: 46124 | B26: AGOS | C26: SHIRAHOSHI GLITTER | D26: STOCK | E26: REMATE | F26: 25 | G26: 25 | H26: =F26-G26 -> 0 | I26: TRUE | J26: PENDIENTE | K26: =A26+15 -> 46139 | L26: =A26+30 -> 46154 | M26: FALSE
A27: 46124 | B27: AGOS | C27: MIKU GITANA | D27: STOCK | E27: REMATE | F27: 15 | G27: 15 | H27: =F27-G27 -> 0 | I27: TRUE | J27: PENDIENTE | K27: =A27+15 -> 46139 | L27: =A27+30 -> 46154 | M27: FALSE
A28: 46124 | B28: AGOS | C28: MIKU 12 AÑOS | D28: STOCK | E28: REMATE | F28: 15 | G28: 15 | H28: =F28-G28 -> 0 | I28: TRUE | J28: PENDIENTE | K28: =A28+15 -> 46139 | L28: =A28+30 -> 46154 | M28: FALSE
A29: 46124 | B29: AGOS | C29: CABALLA ROPA CHILL | D29: STOCK | E29: REMATE | F29: 29 | G29: 29 | H29: =F29-G29 -> 0 | I29: TRUE | J29: PENDIENTE | K29: =A29+15 -> 46139 | L29: =A29+30 -> 46154 | M29: TRUE
A30: 46124 | B30: AGOS | C30: BARCO SIN PIE | D30: STOCK | E30: REMATE | F30: 15 | G30: 15 | H30: =F30-G30 -> 0 | I30: TRUE | J30: PENDIENTE | K30: =A30+15 -> 46139 | L30: =A30+30 -> 46154 | M30: FALSE
A31: 46124 | B31: AGOS | C31: SAKURA GATITA S | D31: STOCK | E31: REMATE | F31: 10 | G31: 10 | H31: =F31-G31 -> 0 | I31: TRUE | J31: PENDIENTE | K31: =A31+15 -> 46139 | L31: =A31+30 -> 46154 | M31: FALSE
... A34: 46125 | B34: AGOS | C34: LL VEST ROJO PELO NARA | D34: STOCK | E34: REMATE | F34: 24 | G34: 24 | H34: =F34-G34 -> 0 | I34: TRUE | J34: PENDIENTE | K34: =A34+15 -> 46140 | L34: =A34+30 -> 46155 | M34: TRUE
A35: 46023 | B35: AGOS | C35: PELIROJA EQUUUUX | D35: AGOSTO | E35: 473 | F35: 35 | G35: 0 | H35: =F35-G35 -> 35 | I35: FALSE | J35: PENDIENTE
A36: 46143 | B36: AGOS | C36: ALBEDO + SHALTEAR | D36: STOCK | E36: REMATE | F36: 105 | G36: 105 | H36: =F36-G36 -> 0 | I36: TRUE | J36: PENDIENTE | K36: =A36+15 -> 46158 | L36: =A36+30 -> 46173 | M36: FALSE
A37: 46192 | B37: AGOS | C37: RELAX SHINECOLOR | D37: STOCK | E37: CAJA | F37: 41 | G37: 0 | H37: =F37-G37 -> 41 | I37: FALSE | J37: PENDIENTE | K37: =A37+15 -> 46207 | L37: =A37+30 -> 46222
A38: 46192 | B38: AGOS | C38: ICHIKA NAKANO | D38: STOCK | E38: CAJA | F38: 41 | G38: 0 | H38: =F38-G38 -> 41 | I38: FALSE | J38: PENDIENTE | K38: =A38+15 -> 46207 | L38: =A38+30 -> 46222
A39: 46192 | B39: AGOS | C39: NINO BLANCA | D39: STOCK | E39: CAJA | F39: 45 | G39: 0 | H39: =F39-G39 -> 45 | I39: FALSE | J39: PENDIENTE | K39: =A39+15 -> 46207 | L39: =A39+30 -> 46222
A40: 46147 | B40: ALEX | C40: GINTOKI | D40: STOCK | E40: 0 | F40: 55 | G40: 55 | H40: =F40-G40 -> 0 | I40: TRUE | J40: PENDIENTE | K40: =A40+15 -> 46162 | L40: =A40+30 -> 46177
A41: 46154 | B41: ALEX | C41: MIKU LOLITA | D41: STOCK | E41: 0 | F41: 70 | G41: 70 | H41: =F41-G41 -> 0 | I41: TRUE | J41: PENDIENTE | K41: =A41+15 -> 46169 | L41: =A41+30 -> 46184
A42: 46059 | B42: ALEXGP | C42: NAMI PILSEN | D42: STOCK | E42: 0 | F42: 40 | G42: 40 | H42: =F42-G42 -> 0 | I42: TRUE | J42: PENDIENTE | K42: =A42+15 -> 46074 | L42: =A42+30 -> 46089
...

Sheet PREVENTAS
A1: CLIENTE | B1: FIGURA | C1: MES | D1: LOTE | E1: PRECIO | F1: ADELANTO | G1: RESTANTE
A3: 17JEAN | B3: ANYA BREAKTIME | C3: JULIO | D3: 417 | E3: 60 | F3: 10 | G3: =E3-F3 -> 50
A4: AGOS | B4: FRIEREN GRANDISTA | C4: JULIO | D4: 433 | E4: 70 | F4: 10 | G4: =E4-F4 -> 60
A5: AGOS | B5: ALBEDO BECUTE | C5: JULIO | D5: 442 | E5: 75 | F5: 10 | G5: =E5-F5 -> 65
A6: AGOS | B6: PELIROJO SENTADO | C6: JULIO | D6: 426 | E6: 40 | F6: 0 | G6: =E6-F6 -> 40
A7: AGOS | B7: AINZ OOAL GOWN | C7: SEPTIEMBRE | D7: 520 | E7: 95 | F7: 0 | G7: =E7-F7 -> 95
A8: AGOS | B8: ALBEDO CONEJA BLANCA | C8: SEPTIEMBRE | D8: 530 | E8: 80 | F8: 0 | G8: =E8-F8 -> 80
A9: AGOS | B9: AI HOSHINO - PREMIUM FIGURE A1 | C9: SEPTIEMBRE | D9: OD3 | E9: 55 | F9: 0 | G9: =E9-F9 -> 55
A10: AGOS | B10: KANA SAKURAGI & HITOMI KOSHIGAYA | C10: SEPTIEMBRE | D10: OD3 | E10: 80 | F10: 0 | G10: =E10-F10 -> 80
A11: AGOS | B11: TOMOE KOGA - Rascal Does Not Dream of Bunny Girl Senpai | C11: SEPTIEMBRE | D11: OD3 | E11: 40 | F11: 0 | G11: =E11-F11 -> 40
A12: AGOS | B12: RUBIA EN SILLA | C12: SEPTIEMBRE | D12: 539 | E12: 45 | F12: 0 | G12: =E12-F12 -> 45
A13: AGOS | B13: MERCURI WITCH | C13: SEPTIEMBRE | D13: 539 | E13: 40 | F13: 0 | G13: =E13-F13 -> 40
A14: AGOS | B14: GUITARRA STELLAR | C14: SEPTIEMBRE | D14: 535 | E14: 40 | F14: 0 | G14: =E14-F14 -> 40
A15: AGOS | B15: LUMINASTA CHICA HIELO | C15: AGOSTO | D15: 473 | E15: 40 | F15: 0 | G15: =E15-F15 -> 40
A16: AGOS | B16: PELIROJA EQUUUUX | C16: AGOSTO | D16: 473 | E16: 35 | F16: 0 | G16: =E16-F16 -> 35
A17: AGOS | B17: PELINEGRA EQUUUUUX | C17: AGOSTO | D17: 473 | E17: 30 | F17: 0 | G17: =E17-F17 -> 30
A18: AGOS | B18: MADE IN ABYSS COREFUL | C18: SEPTIEMBRE | D18: 521 | E18: 70 | F18: 0 | G18: =E18-F18 -> 70
A19: AGOS | B19: TSUKI VAQUITA GLITTER | C19: SEPTIEMBRE | D19: 521 | E19: 80 | F19: 0 | G19: =E19-F19 -> 80
A20: AGOS | B20: AZUNA BUNNY | C20: SEPTIEMBRE | D20: 539 | E20: 65 | F20: 0 | G20: =E20-F20 -> 65
A21: ALEXGP | B21: MIKU DISCOS | C21: JULIO | D21: 419 | E21: 200 | F21: 0 | G21: =E21-F21 -> 200
A22: ALEXGP | B22: AI OSHINO | C22: JULIO | D22: 417 | E22: 60 | F22: 0 | G22: =E22-F22 -> 60
A23: ANGELITO | B23: UZAKI CHAN BUNNIE | C23: SEPTIEMBRE | D23: 521 | E23: 95 | F23: 0 | G23: =E23-F23 -> 95
A24: ANGELITO | B24: TSUKI VAQUITA GLITTER | C24: AGOSTO | D24: 494 | E24: 55 | F24: 0 | G24: =E24-F24 -> 55
A25: ANTONELLA | B25: REM VESTIDO ALMOHADA | C25: JULIO | D25: 417 | E25: 55
A26: ANTONIO | B26: RELAX TIME 100 NOVIAS | C26: SEPTIEMBRE | D26: OD3 | E26: 90 | F26: 0 | G26: =E26-F26 -> 90
A27: ANTONIO | B27: HAKARI HANAZONO - The 100 Girlfriends | C27: SEPTIEMBRE | D27: OD3 | E27: 80 | F27: 0 | G27: =E27-F27 -> 80
A28: ANTONIO | B28: RUBIA CAJA ROSADA | C28: AGOSTO | D28: 473 | E28: 45 | F28: 0 | G28: =E28-F28 -> 45
A29: ARANCIEA | B29: MIKU AMARILLA | C29: JULIO | D29: 467 | E29: 80 | F29: 10 | G29: =E29-F29 -> 70
A30: ARANCIEA | B30: MIKU CEREZO | C30: JULIO | D30: 467 | E30: 85 | F30: 10 | G30: =E30-F30 -> 75
A31: ARANCIEA | B31: MIKU VERDE NOODLE | C31: SEPTIEMBRE | D31: 530 | E31: 60 | F31: 0 | G31: =E31-F31 -> 60
A32: ARANCIEA | B32: HATSUNE MIKU OUTDOOR | C32: SEPTIEMBRE | D32: 521 | E32: 80 | F32: 0 | G32: =E32-F32 -> 80
A33: ARANCIEA | B33: PELIROSA CUTE OREJITAS | C33: JULIO | D33: 442 | E33: 65 | F33: 0 | G33: =E33-F33 -> 65
A34: ARMILENK | B34: PELUCHE TOP GUN | C34: JULIO | D34: 450 | E34: 60 | F34: 10 | G34: =E34-F34 -> 50
A35: ARMILENK | B35: SATONO SEGA | C35: JULIO | D35: 442 | E35: 75 | F35: 10 | G35: =E35-F35 -> 65
A36: BRATHLY | B36: KEI KARUIZAWA - Classroom of the Elite. | C36: SEPTIEMBRE | D36: OD3 | E36: 40 | F36: 0 | G36: =E36-F36 -> 40
A37: BRATHLY | B37: Yui Kotegawa - To LOVE-Ru Darkness | C37: SEPTIEMBRE | D37: OD3 | E37: 55 | F37: 0 | G37: =E37-F37 -> 55
A38: DANIEL CH | B38: GUILLOTINA | C38: JULIO | D38: 442 | E38: 45 | F38: 10 | G38: =E38-F38 -> 35
A39: DANNY JOAO | B39: DRAGON ROJO YUGI | C39: JULIO | D39: 417 | E39: 70
A40: IKKI | B40: DEMONIO PELIROSA | C40: AGOSTO | D40: 494 | E40: 50 | F40: 0 | G40: =E40-F40 -> 50
A41: IKKI | B41: MIKU X KUROMI | C41: JULIO | D41: 467 | E41: 190 | F41: 0 | G41: =E41-F41 -> 190
...
